import React, { Component, ErrorInfo, ReactNode } from 'react';
import './ErrorBoundary.css';

interface Props {
  children: ReactNode;
  fallback?: ReactNode;
  onError?: (error: Error, errorInfo: ErrorInfo) => void;
}

interface State {
  hasError: boolean;
  error: Error | null;
}

export class ErrorBoundary extends Component<Props, State> {
  constructor(props: Props) {
    super(props);
    this.state = { hasError: false, error: null };
  }

  static getDerivedStateFromError(error: Error): State {
    return { hasError: true, error };
  }

  componentDidCatch(error: Error, errorInfo: ErrorInfo) {
    console.error('ErrorBoundary caught an error:', error, errorInfo);
    this.props.onError?.(error, errorInfo);
  }

  handleRetry = () => {
    this.setState({ hasError: false, error: null });
  };

  render() {
    if (this.state.hasError) {
      if (this.props.fallback) {
        return this.props.fallback;
      }

      return (
        <div className="error-boundary">
          <div className="error-boundary__content">
            <div className="error-boundary__icon">⚠️</div>
            <h2 className="error-boundary__title">Something went wrong</h2>
            <p className="error-boundary__message">
              We encountered an unexpected error. Please try again or contact support if the problem persists.
            </p>
            {this.state.error && (
              <details className="error-boundary__details">
                <summary>Error Details</summary>
                <pre className="error-boundary__error-stack">
                  {this.state.error.stack}
                </pre>
              </details>
            )}
            <button
              className="error-boundary__retry-button"
              onClick={this.handleRetry}
            >
              Try Again
            </button>
          </div>
        </div>
      );
    }

    return this.props.children;
  }
}

export default ErrorBoundary;
